Workbook
Name Levered_Raw_Beta: 'Beta Regression'!$J$11
Name Market_Beta: 'Beta Regression'!$J$14
Name Market_Beta_Weight: 'Beta Regression'!$J$15
Name Raw_Beta_Weight: 'Beta Regression'!$J$12

Sheet Financials>

Sheet HistoricalFS
B2: HINDUSTAN UNILEVER LTD
B3: (NSE: HINDUNILVR | BSE: 500696 )
B4: INR 1927.0
B5: 52 Week - (High- 2667.2 & Low- 1926.2)
B8: ="Historical Financial Statements -"&'Data Sheet'!B1 -> Historical Financial Statements -HINDUSTAN UNILEVER LTD
B9: Year | C9: ='Data Sheet'!B16 -> 42825 | D9: ='Data Sheet'!C16 -> 43190 | E9: ='Data Sheet'!D16 -> 43555 | F9: ='Data Sheet'!E16 -> 43921 | G9: ='Data Sheet'!F16 -> 44286 | H9: ='Data Sheet'!G16 -> 44651 | I9: ='Data Sheet'!H16 -> 45016 | J9: ='Data Sheet'!I16 -> 45382 | ... L9: ='Data Sheet'!K16 -> 46112 | M9: LTM
A10: # | B10: Income Statement
B11: Sales | C11: =IFERROR('Data Sheet'!B17,0) -> 33162 | D11: =IFERROR('Data Sheet'!C17,0) -> 35545 | E11: =IFERROR('Data Sheet'!D17,0) -> 39310 | F11: =IFERROR('Data Sheet'!E17,0) -> 39783 | G11: =IFERROR('Data Sheet'!F17,0) -> 47028 | H11: =IFERROR('Data Sheet'!G17,0) -> 52446 | I11: =IFERROR('Data Sheet'!H17,0) -> 60580 | J11: =IFERROR('Data Sheet'!I17,0) -> 61896 | ... L11: =IFERROR('Data Sheet'!K17,0) -> 64468 | M11: =IFERROR(SUM('Data Sheet'!H42:K42),0) -> 66052
B12: Sales Growth | C12: - | D12: =D11/C11-1 -> 0.071859357 | E12: =E11/D11-1 -> 0.10592207 | F12: =F11/E11-1 -> 0.012032562 | G12: =G11/F11-1 -> 0.18211296 | H12: =H11/G11-1 -> 0.11520796 | I12: =I11/H11-1 -> 0.15509286 | J12: =J11/I11-1 -> 0.021723341 | K12: =K11/J11-1 -> -0.0091766835 | ... M12: =M11/L11-1 -> 0.024570329
B14: COGS | C14: =IFERROR(SUM('Data Sheet'!B18,'Data Sheet'!B20:B22)-1*'Data Sheet'!B19,0) -> 18675 | D14: =IFERROR(SUM('Data Sheet'!C18,'Data Sheet'!C20:C22)-1*'Data Sheet'!C19,0) -> 19314 | E14: =IFERROR(SUM('Data Sheet'!D18,'Data Sheet'!D20:D22)-1*'Data Sheet'!D19,0) -> 21081 | F14: =IFERROR(SUM('Data Sheet'!E18,'Data Sheet'!E20:E22)-1*'Data Sheet'!E19,0) -> 20614 | G14: =IFERROR(SUM('Data Sheet'!F18,'Data Sheet'!F20:F22)-1*'Data Sheet'!F19,0) -> 25301 | H14: =IFERROR(SUM('Data Sheet'!G18,'Data Sheet'!G20:G22)-1*'Data Sheet'!G19,0) -> 29066 | I14: =IFERROR(SUM('Data Sheet'!H18,'Data Sheet'!H20:H22)-1*'Data Sheet'!H19,0) -> 35381 | J14: =IFERROR(SUM('Data Sheet'!I18,'Data Sheet'!I20:I22)-1*'Data Sheet'!I19,0) -> 33651 | ... L14: =IFERROR(SUM('Data Sheet'!K18,'Data Sheet'!K20:K22)-1*'Data Sheet'!K19,0) -> 35634 | M14: =IFERROR(SUM('Data Sheet'!H43:K43),0) -> 50705
B15: COGS % Sales | C15: =C14/C11 -> 0.56314456 | D15: =D14/D11 -> 0.54336756 | E15: =E14/E11 -> 0.53627576 | F15: =F14/F11 -> 0.51816102 | G15: =G14/G11 -> 0.53799864 | H15: =H14/H11 -> 0.55420814 | I15: =I14/I11 -> 0.58403764 | J15: =J14/J11 -> 0.54367003 | ... M15: =M14/M11 -> 0.76765276
B17: Gross Profit | C17: =C11-C14 -> 14487 | D17: =D11-D14 -> 16231 | E17: =E11-E14 -> 18229 | F17: =F11-F14 -> 19169 | G17: =G11-G14 -> 21727 | H17: =H11-H14 -> 23380 | I17: =I11-I14 -> 25199 | J17: =J11-J14 -> 28245 | ... M17: =M11-M14 -> 15347
B18: Gross Margins | C18: =C17/C11 -> 0.43685544 | D18: =D17/D11 -> 0.45663244 | E18: =E17/E11 -> 0.46372424 | F18: =F17/F11 -> 0.48183898 | G18: =G17/G11 -> 0.46200136 | H18: =H17/H11 -> 0.44579186 | I18: =I17/I11 -> 0.41596236 | J18: =J17/J11 -> 0.45632997 | ... M18: =M17/M11 -> 0.23234724
B20: Selling & General Expenses | C20: =IFERROR(SUM('Data Sheet'!B23:B24),0) -> 8159 | D20: =IFERROR(SUM('Data Sheet'!C23:C24),0) -> 8732 | E20: =IFERROR(SUM('Data Sheet'!D23:D24),0) -> 9349 | F20: =IFERROR(SUM('Data Sheet'!E23:E24),0) -> 9308 | G20: =IFERROR(SUM('Data Sheet'!F23:F24),0) -> 10101 | H20: =IFERROR(SUM('Data Sheet'!G23:G24),0) -> 10523 | I20: =IFERROR(SUM('Data Sheet'!H23:H24),0) -> 11052 | J20: =IFERROR(SUM('Data Sheet'!I23:I24),0) -> 13586 | ... L20: =IFERROR(SUM('Data Sheet'!K23:K24),0) -> 13795
B21: SG&A Exp % Sales | C21: =C20/C11 -> 0.24603462 | D21: =D20/D11 -> 0.24566043 | E21: =E20/E11 -> 0.23782752 | F21: =F20/F11 -> 0.23396928 | G21: =G20/G11 -> 0.21478694 | H21: =H20/H11 -> 0.20064447 | I21: =I20/I11 -> 0.18243645 | J21: =J20/J11 -> 0.21949722 | ... M21: =M20/M11 -> 0
B23: EBITDA | C23: =C17-C20 -> 6328 | D23: =D17-D20 -> 7499 | E23: =E17-E20 -> 8880 | F23: =F17-F20 -> 9861 | G23: =G17-G20 -> 11626 | H23: =H17-H20 -> 12857 | I23: =I17-I20 -> 14147 | J23: =J17-J20 -> 14659 | ... L23: =L17-L20 -> 15039 | M23: =IFERROR(SUM('Data Sheet'!H51:K51),0) -> 20266
B24: EBITDA Margins | C24: =C23/C11 -> 0.19082082 | D24: =D23/D11 -> 0.21097201 | E24: =E23/E11 -> 0.22589672 | F24: =F23/F11 -> 0.24786969 | G24: =G23/G11 -> 0.24721443 | H24: =H23/H11 -> 0.24514739 | I24: =I23/I11 -> 0.23352592 | J24: =J23/J11 -> 0.23683275 | ... M24: =M23/M11 -> 0.30681887
B26: Interest | C26: =IFERROR('Data Sheet'!B27,0) -> 35 | D26: =IFERROR('Data Sheet'!C27,0) -> 26 | E26: =IFERROR('Data Sheet'!D27,0) -> 33 | F26: =IFERROR('Data Sheet'!E27,0) -> 118 | G26: =IFERROR('Data Sheet'!F27,0) -> 117 | H26: =IFERROR('Data Sheet'!G27,0) -> 106 | I26: =IFERROR('Data Sheet'!H27,0) -> 114 | J26: =IFERROR('Data Sheet'!I27,0) -> 334 | ... L26: =IFERROR('Data Sheet'!K27,0) -> 410 | M26: =IFERROR(SUM('Data Sheet'!H46:K46),0) -> 363
B27: Interest % Sales | C27: =C26/C11 -> 0.0010554249 | D27: =D26/D11 -> 0.00073146715 | E27: =E26/E11 -> 0.00083948105 | F27: =F26/F11 -> 0.002966091 | G27: =G26/G11 -> 0.0024878796 | H27: =H26/H11 -> 0.0020211265 | I27: =I26/I11 -> 0.0018818092 | J27: =J26/J11 -> 0.0053961484 | ... M27: =M26/M11 -> 0.0054956701
B29: Depriciation | C29: =IFERROR('Data Sheet'!B26,0) -> 432 | D29: =IFERROR('Data Sheet'!C26,0) -> 520 | E29: =IFERROR('Data Sheet'!D26,0) -> 565 | F29: =IFERROR('Data Sheet'!E26,0) -> 1002 | G29: =IFERROR('Data Sheet'!F26,0) -> 1074 | H29: =IFERROR('Data Sheet'!G26,0) -> 1091 | I29: =IFERROR('Data Sheet'!H26,0) -> 1137 | J29: =IFERROR('Data Sheet'!I26,0) -> 1216 | ... L29: =IFERROR('Data Sheet'!K26,0) -> 1333 | M29: =IFERROR(SUM('Data Sheet'!H45:K45),0) -> 1360
B30: Depreciation% Sales | C30: =C29/C11 -> 0.013026959 | D30: =D29/D11 -> 0.014629343 | E30: =E29/E11 -> 0.014372933 | F30: =F29/F11 -> 0.025186638 | G30: =G29/G11 -> 0.022837459 | H30: =H29/H11 -> 0.020802349 | I30: =I29/I11 -> 0.01876857 | J30: =J29/J11 -> 0.019645858 | ... M30: =M29/M11 -> 0.020589838
B32: Earning Before Tax | C32: =C23-SUM(C26,C29) -> 5861 | D32: =D23-SUM(D26,D29) -> 6953 | E32: =E23-SUM(E26,E29) -> 8282 | F32: =F23-SUM(F26,F29) -> 8741 | G32: =G23-SUM(G26,G29) -> 10435 | H32: =H23-SUM(H26,H29) -> 11660 | I32: =I23-SUM(I26,I29) -> 12896 | J32: =J23-SUM(J26,J29) -> 13109 | ... M32: =M23-SUM(M26,M29) -> 18543
B33: EBT% Sales | C33: =C32/C11 -> 0.17673844 | D33: =D32/D11 -> 0.1956112 | E33: =E32/E11 -> 0.2106843 | F33: =F32/F11 -> 0.21971696 | G33: =G32/G11 -> 0.22188909 | H33: =H32/H11 -> 0.22232391 | I33: =I32/I11 -> 0.21287554 | J33: =J32/J11 -> 0.21179075 | ... M33: =M32/M11 -> 0.28073336
B35: Tax | C35: =IFERROR('Data Sheet'!B29,0) -> 1977 | D35: =IFERROR('Data Sheet'!C29,0) -> 2079 | E35: =IFERROR('Data Sheet'!D29,0) -> 2544 | F35: =IFERROR('Data Sheet'!E29,0) -> 2409 | G35: =IFERROR('Data Sheet'!F29,0) -> 2606 | H35: =IFERROR('Data Sheet'!G29,0) -> 2987 | I35: =IFERROR('Data Sheet'!H29,0) -> 3201 | J35: =IFERROR('Data Sheet'!I29,0) -> 3644 | ... L35: =IFERROR('Data Sheet'!K29,0) -> 3160 | M35: =IFERROR(SUM('Data Sheet'!H48:K48),0) -> 3586
B36: Effective Tax Rtae | C36: =C35/C32 -> 0.33731445 | D36: =D35/D32 -> 0.29900762 | E36: =E35/E32 -> 0.30717218 | F36: =F35/F32 -> 0.27559776 | G36: =G35/G32 -> 0.24973646 | H36: =H35/H32 -> 0.25617496 | I36: =I35/I32 -> 0.2482165 | J36: =J35/J32 -> 0.27797696 | ... M36: =M35/M32 -> 0.19338834
B38: Net Profit | C38: =C32-C35 -> 3884 | D38: =D32-D35 -> 4874 | E38: =E32-E35 -> 5738 | F38: =F32-F35 -> 6332 | G38: =G32-G35 -> 7829 | H38: =H32-H35 -> 8673 | I38: =I32-I35 -> 9695 | J38: =J32-J35 -> 9465 | ... M38: =M32-M35 -> 14957
B39: Net Margins | C39: =C38/C11 -> 0.11712201 | D39: =D38/D11 -> 0.13712196 | E39: =E38/E11 -> 0.14596795 | F39: =F38/F11 -> 0.15916346 | G39: =G38/G11 -> 0.16647529 | H39: =H38/H11 -> 0.16537009 | I39: =I38/I11 -> 0.16003632 | J39: =J38/J11 -> 0.1529178 | ... M39: =M38/M11 -> 0.2264428
B41: No. of Equity Shares | C41: =IFERROR('Data Sheet'!B93,0) -> 216.43 | D41: =IFERROR('Data Sheet'!C93,0) -> 216.45 | E41: =IFERROR('Data Sheet'!D93,0) -> 216.47 | F41: =IFERROR('Data Sheet'!E93,0) -> 216.48 | G41: =IFERROR('Data Sheet'!F93,0) -> 234.96 | H41: =IFERROR('Data Sheet'!G93,0) -> 234.96 | I41: =IFERROR('Data Sheet'!H93,0) -> 234.96 | J41: =IFERROR('Data Sheet'!I93,0) -> 234.96 | ... M41: =IFERROR('Data Sheet'!L93,0) -> 0
B43: Earning Per Share | C43: =IFERROR(C38/C41,0) -> 17.945756 | D43: =IFERROR(D38/D41,0) -> 22.517903 | E43: =IFERROR(E38/E41,0) -> 26.507137 | F43: =IFERROR(F38/F41,0) -> 29.249815 | G43: =IFERROR(G38/G41,0) -> 33.320565 | H43: =IFERROR(H38/H41,0) -> 36.912666 | I43: =IFERROR(I38/I41,0) -> 41.262343 | J43: =IFERROR(J38/J41,0) -> 40.283453 | ... M43: =IFERROR(M38/M41,0) -> 0
B44: EPS Growth % | D44: =IFERROR(D43/C43-1,0) -> 0.25477591 | E44: =IFERROR(E43/D43-1,0) -> 0.17715836 | F44: =IFERROR(F43/E43-1,0) -> 0.10346941 | G44: =IFERROR(G43/F43-1,0) -> 0.13917182 | H44: =IFERROR(H43/G43-1,0) -> 0.10780432 | I44: =IFERROR(I43/H43-1,0) -> 0.11783697 | J44: =IFERROR(J43/I43-1,0) -> -0.023723569 | K44: =IFERROR(K43/J43-1,0) -> -0.015742208 | ... M44: =IFERROR(M43/L43-1,0) -> -1
B46: Dividend per Share | C46: =IFERROR('Data Sheet'!B31/HistoricalFS!C41,0) -> 16.966225 | D46: =IFERROR('Data Sheet'!C31/HistoricalFS!D41,0) -> 19.95842 | E46: =IFERROR('Data Sheet'!D31/HistoricalFS!E41,0) -> 21.952234 | F46: =IFERROR('Data Sheet'!E31/HistoricalFS!F41,0) -> 24.944568 | G46: =IFERROR('Data Sheet'!F31/HistoricalFS!G41,0) -> 40.506895 | H46: =IFERROR('Data Sheet'!G31/HistoricalFS!H41,0) -> 34.005788 | I46: =IFERROR('Data Sheet'!H31/HistoricalFS!I41,0) -> 39.006639 | J46: =IFERROR('Data Sheet'!I31/HistoricalFS!J41,0) -> 42.00715 | ... M46: =IFERROR('Data Sheet'!L31/HistoricalFS!M41,0) -> 0
B47: Dividend Payout Ratio | C47: =IFERROR(C46/C43,0) -> 0.9454171 | D47: =IFERROR(D46/D43,0) -> 0.88633566 | E47: =IFERROR(E46/E43,0) -> 0.82816312 | F47: =IFERROR(F46/F43,0) -> 0.85281112 | G47: =IFERROR(G46/G43,0) -> 1.2156725 | H47: =IFERROR(H46/H43,0) -> 0.92124986 | I47: =IFERROR(I46/I43,0) -> 0.94533265 | J47: =IFERROR(J46/J43,0) -> 1.0427892 | ... M47: =IFERROR(M46/M43,0) -> 0
B49: Retained Earnings | C49: =IFERROR(IF(C43>C46,1-C47,0),0) -> 0.054582904 | D49: =IFERROR(IF(D43>D46,1-D47,0),0) -> 0.11366434 | E49: =IFERROR(IF(E43>E46,1-E47,0),0) -> 0.17183688 | F49: =IFERROR(IF(F43>F46,1-F47,0),0) -> 0.14718888 | G49: =IFERROR(IF(G43>G46,1-G47,0),0) -> 0 | H49: =IFERROR(IF(H43>H46,1-H47,0),0) -> 0.078750144 | I49: =IFERROR(IF(I43>I46,1-I47,0),0) -> 0.054667354 | J49: =IFERROR(IF(J43>J46,1-J47,0),0) -> 0 | ... M49: =IFERROR(IF(M43>M46,1-M47,0),0) -> 0
A53: # | B53: Balance Sheet
B54: Equity Share Capital | C54: =IFERROR('Data Sheet'!B57,0) -> 216 | D54: =IFERROR('Data Sheet'!C57,0) -> 216 | E54: =IFERROR('Data Sheet'!D57,0) -> 216 | F54: =IFERROR('Data Sheet'!E57,0) -> 216 | G54: =IFERROR('Data Sheet'!F57,0) -> 235 | H54: =IFERROR('Data Sheet'!G57,0) -> 235 | I54: =IFERROR('Data Sheet'!H57,0) -> 235 | J54: =IFERROR('Data Sheet'!I57,0) -> 235 | ... L54: =IFERROR('Data Sheet'!K57,0) -> 235
B55: Reserves | C55: =IFERROR('Data Sheet'!B58,0) -> 6528 | D55: =IFERROR('Data Sheet'!C58,0) -> 7065 | E55: =IFERROR('Data Sheet'!D58,0) -> 7651 | F55: =IFERROR('Data Sheet'!E58,0) -> 8013 | G55: =IFERROR('Data Sheet'!F58,0) -> 47439 | H55: =IFERROR('Data Sheet'!G58,0) -> 48826 | I55: =IFERROR('Data Sheet'!H58,0) -> 50069 | J55: =IFERROR('Data Sheet'!I58,0) -> 50983 | ... L55: =IFERROR('Data Sheet'!K58,0) -> 48504
B56: Borrowings | C56: =IFERROR('Data Sheet'!B59,0) -> 277 | D56: =IFERROR('Data Sheet'!C59,0) -> 0 | E56: =IFERROR('Data Sheet'!D59,0) -> 99 | F56: =IFERROR('Data Sheet'!E59,0) -> 0 | G56: =IFERROR('Data Sheet'!F59,0) -> 0 | H56: =IFERROR('Data Sheet'!G59,0) -> 1043 | I56: =IFERROR('Data Sheet'!H59,0) -> 1219 | J56: =IFERROR('Data Sheet'!I59,0) -> 1484 | ... L56: =IFERROR('Data Sheet'!K59,0) -> 1478
B57: Other Liabilities | C57: =IFERROR('Data Sheet'!B60,0) -> 8685 | D57: =IFERROR('Data Sheet'!C60,0) -> 10581 | E57: =IFERROR('Data Sheet'!D60,0) -> 10663 | F57: =IFERROR('Data Sheet'!E60,0) -> 11924 | G57: =IFERROR('Data Sheet'!F60,0) -> 21066 | H57: =IFERROR('Data Sheet'!G60,0) -> 20402 | I57: =IFERROR('Data Sheet'!H60,0) -> 21554 | J57: =IFERROR('Data Sheet'!I60,0) -> 25787 | ... L57: =IFERROR('Data Sheet'!K60,0) -> 29521
B58: Total Liabilities | C58: =IFERROR(SUM(C54:C57),0) -> 15706 | D58: =IFERROR(SUM(D54:D57),0) -> 17862 | E58: =IFERROR(SUM(E54:E57),0) -> 18629 | F58: =IFERROR(SUM(F54:F57),0) -> 20153 | G58: =IFERROR(SUM(G54:G57),0) -> 68740 | H58: =IFERROR(SUM(H54:H57),0) -> 70506 | I58: =IFERROR(SUM(I54:I57),0) -> 73077 | J58: =IFERROR(SUM(J54:J57),0) -> 78489 | ... L58: =IFERROR(SUM(L54:L57),0) -> 79738
B60: Fixed Asset Net Block | C60: =IFERROR('Data Sheet'!B62,0) -> 4419 | D60: =IFERROR('Data Sheet'!C62,0) -> 4528 | E60: =IFERROR('Data Sheet'!D62,0) -> 4715 | F60: =IFERROR('Data Sheet'!E62,0) -> 5479 | G60: =IFERROR('Data Sheet'!F62,0) -> 51443 | H60: =IFERROR('Data Sheet'!G62,0) -> 51473 | I60: =IFERROR('Data Sheet'!H62,0) -> 52678 | J60: =IFERROR('Data Sheet'!I62,0) -> 53744 | ... L60: =IFERROR('Data Sheet'!K62,0) -> 57428
...

Sheet Forecasting
B2: HINDUSTAN UNILEVER LTD
B3: (NSE: HINDUNILVR | BSE: 500696 )
B4: INR 1927.0
B5: 52 Week - (High- 2667.2 & Low- 1926.2)
B7: ='Data Sheet'!B1&" -"&'Data Sheet'!A17&" Forecasting" -> HINDUSTAN UNILEVER LTD -Sales Forecasting | G7: ='Data Sheet'!B1&" -"&HistoricalFS!B23&" Forecasting" -> HINDUSTAN UNILEVER LTD -EBITDA Forecasting | L7: ='Data Sheet'!B1&" -"&HistoricalFS!B43&" Forecasting" -> HINDUSTAN UNILEVER LTD -Earning Per Share Forecasting
B8: Year Weight | C8: Year | D8: Sales | E8: Sales Growth | G8: Year Weight | H8: Year | I8: Sales | J8: Sales Growth | L8: Year Weight | M8: Year | N8: Sales | O8: Sales Growth
B9: 1 | C9: ='Data Sheet'!B16 -> 42825 | D9: {=TRANSPOSE('Data Sheet'!B17:K17)} -> 33162 | G9: 1 | H9: 41364 | I9: {=TRANSPOSE(HistoricalFS!C23:L23)} -> 6328 | L9: 1 | M9: 41364 | N9: {=TRANSPOSE(HistoricalFS!C43:L43)} -> 17.945756
B10: =B9+1 -> 2 | C10: =C9+365 -> 43190 | D10: 35545 | E10: =IFERROR(D10/D9-1,0) -> 0.071859357 | G10: =G9+1 -> 2 | H10: 41729 | I10: 7499 | J10: =IFERROR(I10/I9-1,0) -> 0.18505057 | L10: =L9+1 -> 2 | M10: 41729 | N10: 22.517903 | O10: =IFERROR(N10/N9-1,0) -> 0.25477591
B11: =B10+1 -> 3 | C11: =C10+365 -> 43555 | D11: 39310 | E11: =IFERROR(D11/D10-1,0) -> 0.10592207 | G11: =G10+1 -> 3 | H11: 42094 | I11: 8880 | J11: =IFERROR(I11/I10-1,0) -> 0.18415789 | L11: =L10+1 -> 3 | M11: 42094 | N11: 26.507137 | O11: =IFERROR(N11/N10-1,0) -> 0.17715836
B12: =B11+1 -> 4 | C12: =C11+365 -> 43920 | D12: 39783 | E12: =IFERROR(D12/D11-1,0) -> 0.012032562 | G12: =G11+1 -> 4 | H12: 42459 | I12: 9861 | J12: =IFERROR(I12/I11-1,0) -> 0.11047297 | L12: =L11+1 -> 4 | M12: 42459 | N12: 29.249815 | O12: =IFERROR(N12/N11-1,0) -> 0.10346941
B13: =B12+1 -> 5 | C13: =C12+365 -> 44285 | D13: 47028 | E13: =IFERROR(D13/D12-1,0) -> 0.18211296 | G13: =G12+1 -> 5 | H13: 42824 | I13: 11626 | J13: =IFERROR(I13/I12-1,0) -> 0.17898793 | L13: =L12+1 -> 5 | M13: 42824 | N13: 33.320565 | O13: =IFERROR(N13/N12-1,0) -> 0.13917182
B14: =B13+1 -> 6 | C14: =C13+365 -> 44650 | D14: 52446 | E14: =IFERROR(D14/D13-1,0) -> 0.11520796 | G14: =G13+1 -> 6 | H14: 43189 | I14: 12857 | J14: =IFERROR(I14/I13-1,0) -> 0.10588336 | L14: =L13+1 -> 6 | M14: 43189 | N14: 36.912666 | O14: =IFERROR(N14/N13-1,0) -> 0.10780432
B15: =B14+1 -> 7 | C15: =C14+365 -> 45015 | D15: 60580 | E15: =IFERROR(D15/D14-1,0) -> 0.15509286 | G15: =G14+1 -> 7 | H15: 43554 | I15: 14147 | J15: =IFERROR(I15/I14-1,0) -> 0.10033445 | L15: =L14+1 -> 7 | M15: 43554 | N15: 41.262343 | O15: =IFERROR(N15/N14-1,0) -> 0.11783697
B16: =B15+1 -> 8 | C16: =C15+365 -> 45380 | D16: 61896 | E16: =IFERROR(D16/D15-1,0) -> 0.021723341 | G16: =G15+1 -> 8 | H16: 43919 | I16: 14659 | J16: =IFERROR(I16/I15-1,0) -> 0.036191419 | L16: =L15+1 -> 8 | M16: 43919 | N16: 40.283453 | O16: =IFERROR(N16/N15-1,0) -> -0.023723569
B17: =B16+1 -> 9 | C17: =C16+365 -> 45745 | D17: 61328 | E17: =IFERROR(D17/D16-1,0) -> -0.0091766835 | G17: =G16+1 -> 9 | H17: 44284 | I17: 14698 | J17: =IFERROR(I17/I16-1,0) -> 0.0026604816 | L17: =L16+1 -> 9 | M17: 44284 | N17: 39.649302 | O17: =IFERROR(N17/N16-1,0) -> -0.015742208
B18: =B17+1 -> 10 | C18: =C17+365 -> 46110 | D18: 64468 | E18: =IFERROR(D18/D17-1,0) -> 0.051200104 | G18: =G17+1 -> 10 | H18: 44649 | I18: 15039 | J18: =IFERROR(I18/I17-1,0) -> 0.023200435 | L18: =L17+1 -> 10 | M18: 44649 | N18: 43.139258 | O18: =IFERROR(N18/N17-1,0) -> 0.08802061
B19: =B18+1 -> 11 | C19: =C18+365 -> 46475 | D19: =IFERROR(FORECAST(B19,$D$9:$D$18,$B$9:$B$18),0) -> 70987.067 | E19: =IFERROR(D19/D18-1,0) -> 0.10112097 | G19: =G18+1 -> 11 | H19: 45014 | I19: =IFERROR(FORECAST(G19,$I$9:$I$18,$G$9:$G$18),0) -> 17285.267 | J19: =IFERROR(I19/I18-1,0) -> 0.14936277 | L19: =L18+1 -> 11 | M19: 45014 | N19: =IFERROR(FORECAST(L19,$N$9:$N$18,$L$9:$L$18),0) -> 48.251239 | O19: =IFERROR(N19/N18-1,0) -> 0.11849951
B20: =B19+1 -> 12 | C20: =C19+365 -> 46840 | D20: =IFERROR(FORECAST(B20,$D$9:$D$18,$B$9:$B$18),0) -> 74883.879 | E20: =IFERROR(D20/D19-1,0) -> 0.054894677 | G20: =G19+1 -> 12 | H20: 45379 | I20: =IFERROR(FORECAST(G20,$I$9:$I$18,$G$9:$G$18),0) -> 18326.333 | J20: =IFERROR(I20/I19-1,0) -> 0.060228557 | L20: =L19+1 -> 12 | M20: 45379 | N20: =IFERROR(FORECAST(L20,$N$9:$N$18,$L$9:$L$18),0) -> 51.00986 | O20: =IFERROR(N20/N19-1,0) -> 0.057172038
B21: =B20+1 -> 13 | C21: =C20+365 -> 47205 | D21: =IFERROR(FORECAST(B21,$D$9:$D$18,$B$9:$B$18),0) -> 78780.691 | E21: =IFERROR(D21/D20-1,0) -> 0.052038065 | G21: =G20+1 -> 13 | H21: 45744 | I21: =IFERROR(FORECAST(G21,$I$9:$I$18,$G$9:$G$18),0) -> 19367.4 | J21: =IFERROR(I21/I20-1,0) -> 0.056807145 | L21: =L20+1 -> 13 | M21: 45744 | N21: =IFERROR(FORECAST(L21,$N$9:$N$18,$L$9:$L$18),0) -> 53.768482 | O21: =IFERROR(N21/N20-1,0) -> 0.054080164
B22: =B21+1 -> 14 | C22: =C21+365 -> 47570 | D22: =IFERROR(FORECAST(B22,$D$9:$D$18,$B$9:$B$18),0) -> 82677.503 | E22: =IFERROR(D22/D21-1,0) -> 0.049464051 | G22: =G21+1 -> 14 | H22: 46109 | I22: =IFERROR(FORECAST(G22,$I$9:$I$18,$G$9:$G$18),0) -> 20408.467 | J22: =IFERROR(I22/I21-1,0) -> 0.053753558 | L22: =L21+1 -> 14 | M22: 46109 | N22: =IFERROR(FORECAST(L22,$N$9:$N$18,$L$9:$L$18),0) -> 56.527104 | O22: =IFERROR(N22/N21-1,0) -> 0.051305552
B23: =B22+1 -> 15 | C23: =C22+365 -> 47935 | D23: =IFERROR(FORECAST(B23,$D$9:$D$18,$B$9:$B$18),0) -> 86574.315 | E23: =IFERROR(D23/D22-1,0) -> 0.047132678 | G23: =G22+1 -> 15 | H23: 46474 | I23: =IFERROR(FORECAST(G23,$I$9:$I$18,$G$9:$G$18),0) -> 21449.533 | J23: =IFERROR(I23/I22-1,0) -> 0.051011508 | L23: =L22+1 -> 15 | M23: 46474 | N23: =IFERROR(FORECAST(L23,$N$9:$N$18,$L$9:$L$18),0) -> 59.285725 | O23: =IFERROR(N23/N22-1,0) -> 0.048801751

Sheet Ratio Analysis
A1: _
B2: HINDUSTAN UNILEVER LTD
B3: (NSE: HINDUNILVR | BSE: 500696 )
B4: INR 1927.0
B5: 52 Week - (High- 2667.2 & Low- 1926.2)
B7: ="Ratio Analysis -"&'Data Sheet'!B1 -> Ratio Analysis -HINDUSTAN UNILEVER LTD
B8: Year | C8: ='Data Sheet'!B16 -> 42825 | D8: ='Data Sheet'!C16 -> 43190 | E8: ='Data Sheet'!D16 -> 43555 | F8: ='Data Sheet'!E16 -> 43921 | G8: ='Data Sheet'!F16 -> 44286 | H8: ='Data Sheet'!G16 -> 44651 | I8: ='Data Sheet'!H16 -> 45016 | J8: ='Data Sheet'!I16 -> 45382 | ... L8: ='Data Sheet'!K16 -> 46112 | M8: Trend | N8: Mean | O8: Median
B10: SalesGrowth | D10: =IFERROR(HistoricalFS!D12,0) -> 0.071859357 | E10: =IFERROR(HistoricalFS!E12,0) -> 0.10592207 | F10: =IFERROR(HistoricalFS!F12,0) -> 0.012032562 | G10: =IFERROR(HistoricalFS!G12,0) -> 0.18211296 | H10: =IFERROR(HistoricalFS!H12,0) -> 0.11520796 | I10: =IFERROR(HistoricalFS!I12,0) -> 0.15509286 | J10: =IFERROR(HistoricalFS!J12,0) -> 0.021723341 | K10: =IFERROR(HistoricalFS!K12,0) -> -0.0091766835 | L10: =IFERROR(HistoricalFS!L12,0) -> 0.051200104 | N10: =IFERROR(AVERAGE(D10:L10),0) -> 0.078441615 | O10: =IFERROR(MEDIAN(C10:L10),0) -> 0.071859357
B11: EBITDA Growth | D11: =IFERROR(HistoricalFS!D23/HistoricalFS!C23-1,0) -> 0.18505057 | E11: =IFERROR(HistoricalFS!E23/HistoricalFS!D23-1,0) -> 0.18415789 | F11: =IFERROR(HistoricalFS!F23/HistoricalFS!E23-1,0) -> 0.11047297 | G11: =IFERROR(HistoricalFS!G23/HistoricalFS!F23-1,0) -> 0.17898793 | H11: =IFERROR(HistoricalFS!H23/HistoricalFS!G23-1,0) -> 0.10588336 | I11: =IFERROR(HistoricalFS!I23/HistoricalFS!H23-1,0) -> 0.10033445 | J11: =IFERROR(HistoricalFS!J23/HistoricalFS!I23-1,0) -> 0.036191419 | K11: =IFERROR(HistoricalFS!K23/HistoricalFS!J23-1,0) -> 0.0026604816 | L11: =IFERROR(HistoricalFS!L23/HistoricalFS!K23-1,0) -> 0.023200435 | N11: =IFERROR(AVERAGE(D11:L11),0) -> 0.10299328 | O11: =IFERROR(MEDIAN(C11:L11),0) -> 0.10588336
B12: EBT Growth | D12: =IFERROR(HistoricalFS!D32/HistoricalFS!C32-1,0) -> 0.18631633 | E12: =IFERROR(HistoricalFS!E32/HistoricalFS!D32-1,0) -> 0.19114051 | F12: =IFERROR(HistoricalFS!F32/HistoricalFS!E32-1,0) -> 0.055421396 | G12: =IFERROR(HistoricalFS!G32/HistoricalFS!F32-1,0) -> 0.19379934 | H12: =IFERROR(HistoricalFS!H32/HistoricalFS!G32-1,0) -> 0.11739339 | I12: =IFERROR(HistoricalFS!I32/HistoricalFS!H32-1,0) -> 0.10600343 | J12: =IFERROR(HistoricalFS!J32/HistoricalFS!I32-1,0) -> 0.016516749 | K12: =IFERROR(HistoricalFS!K32/HistoricalFS!J32-1,0) -> -0.0034327561 | L12: =IFERROR(HistoricalFS!L32/HistoricalFS!K32-1,0) -> 0.017758726 | N12: =IFERROR(AVERAGE(D12:L12),0) -> 0.097879679 | O12: =IFERROR(MEDIAN(C12:L12),0) -> 0.10600343
B13: Net Profit Growth | D13: =IFERROR(HistoricalFS!D38/HistoricalFS!C38-1,0) -> 0.25489186 | E13: =IFERROR(HistoricalFS!E38/HistoricalFS!D38-1,0) -> 0.17726713 | F13: =IFERROR(HistoricalFS!F38/HistoricalFS!E38-1,0) -> 0.10352039 | G13: =IFERROR(HistoricalFS!G38/HistoricalFS!F38-1,0) -> 0.23641819 | H13: =IFERROR(HistoricalFS!H38/HistoricalFS!G38-1,0) -> 0.10780432 | I13: =IFERROR(HistoricalFS!I38/HistoricalFS!H38-1,0) -> 0.11783697 | J13: =IFERROR(HistoricalFS!J38/HistoricalFS!I38-1,0) -> -0.023723569 | K13: =IFERROR(HistoricalFS!K38/HistoricalFS!J38-1,0) -> -0.015742208 | L13: =IFERROR(HistoricalFS!L38/HistoricalFS!K38-1,0) -> 0.08802061 | N13: =IFERROR(AVERAGE(D13:L13),0) -> 0.11625485 | O13: =IFERROR(MEDIAN(C13:L13),0) -> 0.10780432
B14: Dividend Growth | D14: =IFERROR(HistoricalFS!D46/HistoricalFS!C46-1,0) -> 0.17636188 | E14: =IFERROR(HistoricalFS!E46/HistoricalFS!D46-1,0) -> 0.099898369 | F14: =IFERROR(HistoricalFS!F46/HistoricalFS!E46-1,0) -> 0.13631114 | G14: =IFERROR(HistoricalFS!G46/HistoricalFS!F46-1,0) -> 0.6238764 | H14: =IFERROR(HistoricalFS!H46/HistoricalFS!G46-1,0) -> -0.16049383 | I14: =IFERROR(HistoricalFS!I46/HistoricalFS!H46-1,0) -> 0.14705882 | J14: =IFERROR(HistoricalFS!J46/HistoricalFS!I46-1,0) -> 0.076923077 | K14: =IFERROR(HistoricalFS!K46/HistoricalFS!J46-1,0) -> 0.26190476 | L14: =IFERROR(HistoricalFS!L46/HistoricalFS!K46-1,0) -> -0.22641509 | N14: =IFERROR(AVERAGE(D14:L14),0) -> 0.12615839 | O14: =IFERROR(MEDIAN(C14:L14),0) -> 0.13631114
B16: Gross Margin | C16: =IFERROR(HistoricalFS!C18,0) -> 0.43685544 | D16: =IFERROR(HistoricalFS!D18,0) -> 0.45663244 | E16: =IFERROR(HistoricalFS!E18,0) -> 0.46372424 | F16: =IFERROR(HistoricalFS!F18,0) -> 0.48183898 | G16: =IFERROR(HistoricalFS!G18,0) -> 0.46200136 | H16: =IFERROR(HistoricalFS!H18,0) -> 0.44579186 | I16: =IFERROR(HistoricalFS!I18,0) -> 0.41596236 | J16: =IFERROR(HistoricalFS!J18,0) -> 0.45632997 | ... L16: =IFERROR(HistoricalFS!L18,0) -> 0.44726066 | N16: =IFERROR(AVERAGE(C16:L16),0) -> 0.45198443 | O16: =IFERROR(MEDIAN(C16:L16),0) -> 0.45488851
B17: EBITDA Margin | C17: =IFERROR(HistoricalFS!C24,0) -> 0.19082082 | D17: =IFERROR(HistoricalFS!D24,0) -> 0.21097201 | E17: =IFERROR(HistoricalFS!E24,0) -> 0.22589672 | F17: =IFERROR(HistoricalFS!F24,0) -> 0.24786969 | G17: =IFERROR(HistoricalFS!G24,0) -> 0.24721443 | H17: =IFERROR(HistoricalFS!H24,0) -> 0.24514739 | I17: =IFERROR(HistoricalFS!I24,0) -> 0.23352592 | J17: =IFERROR(HistoricalFS!J24,0) -> 0.23683275 | ... L17: =IFERROR(HistoricalFS!L24,0) -> 0.23327853 | N17: =IFERROR(AVERAGE(C17:L17),0) -> 0.23112204 | O17: =IFERROR(MEDIAN(C17:L17),0) -> 0.23517933
B18: EBIT Margin | C18: =IFERROR((HistoricalFS!C23-HistoricalFS!C29)/HistoricalFS!C11,0) -> 0.17779386 | D18: =IFERROR((HistoricalFS!D23-HistoricalFS!D29)/HistoricalFS!D11,0) -> 0.19634266 | E18: =IFERROR((HistoricalFS!E23-HistoricalFS!E29)/HistoricalFS!E11,0) -> 0.21152379 | F18: =IFERROR((HistoricalFS!F23-HistoricalFS!F29)/HistoricalFS!F11,0) -> 0.22268306 | G18: =IFERROR((HistoricalFS!G23-HistoricalFS!G29)/HistoricalFS!G11,0) -> 0.22437697 | H18: =IFERROR((HistoricalFS!H23-HistoricalFS!H29)/HistoricalFS!H11,0) -> 0.22434504 | I18: =IFERROR((HistoricalFS!I23-HistoricalFS!I29)/HistoricalFS!I11,0) -> 0.21475735 | J18: =IFERROR((HistoricalFS!J23-HistoricalFS!J29)/HistoricalFS!J11,0) -> 0.21718689 | ... L18: =IFERROR((HistoricalFS!L23-HistoricalFS!L29)/HistoricalFS!L11,0) -> 0.2126016 | N18: =IFERROR(AVERAGE(C18:L18),0) -> 0.21208422 | O18: =IFERROR(MEDIAN(C18:L18),0) -> 0.21597212
B19: EBT Margin | C19: =IFERROR(HistoricalFS!C33,0) -> 0.17673844 | D19: =IFERROR(HistoricalFS!D33,0) -> 0.1956112 | E19: =IFERROR(HistoricalFS!E33,0) -> 0.2106843 | F19: =IFERROR(HistoricalFS!F33,0) -> 0.21971696 | G19: =IFERROR(HistoricalFS!G33,0) -> 0.22188909 | H19: =IFERROR(HistoricalFS!H33,0) -> 0.22232391 | I19: =IFERROR(HistoricalFS!I33,0) -> 0.21287554 | J19: =IFERROR(HistoricalFS!J33,0) -> 0.21179075 | ... L19: =IFERROR(HistoricalFS!L33,0) -> 0.20624186 | N19: =IFERROR(AVERAGE(C19:L19),0) -> 0.20908906 | O19: =IFERROR(MEDIAN(C19:L19),0) -> 0.21233314
B20: Net Profit Margin | C20: =IFERROR(HistoricalFS!C39,0) -> 0.11712201 | D20: =IFERROR(HistoricalFS!D39,0) -> 0.13712196 | E20: =IFERROR(HistoricalFS!E39,0) -> 0.14596795 | F20: =IFERROR(HistoricalFS!F39,0) -> 0.15916346 | G20: =IFERROR(HistoricalFS!G39,0) -> 0.16647529 | H20: =IFERROR(HistoricalFS!H39,0) -> 0.16537009 | I20: =IFERROR(HistoricalFS!I39,0) -> 0.16003632 | J20: =IFERROR(HistoricalFS!J39,0) -> 0.1529178 | ... L20: =IFERROR(HistoricalFS!L39,0) -> 0.15722529 | N20: =IFERROR(AVERAGE(C20:L20),0) -> 0.15133047 | O20: =IFERROR(MEDIAN(C20:L20),0) -> 0.15507154
B22: SalesExpenses%Sales | C22: =IFERROR(HistoricalFS!C21,0) -> 0.24603462 | D22: =IFERROR(HistoricalFS!D21,0) -> 0.24566043 | E22: =IFERROR(HistoricalFS!E21,0) -> 0.23782752 | F22: =IFERROR(HistoricalFS!F21,0) -> 0.23396928 | G22: =IFERROR(HistoricalFS!G21,0) -> 0.21478694 | H22: =IFERROR(HistoricalFS!H21,0) -> 0.20064447 | I22: =IFERROR(HistoricalFS!I21,0) -> 0.18243645 | J22: =IFERROR(HistoricalFS!J21,0) -> 0.21949722 | ... L22: =IFERROR(HistoricalFS!L21,0) -> 0.21398213 | N22: =IFERROR(AVERAGE(C22:L22),0) -> 0.2208624 | O22: =IFERROR(MEDIAN(C22:L22),0) -> 0.21714208
B23: Depreciation%Sales | C23: =IFERROR(HistoricalFS!C30,0) -> 0.013026959 | D23: =IFERROR(HistoricalFS!D30,0) -> 0.014629343 | E23: =IFERROR(HistoricalFS!E30,0) -> 0.014372933 | F23: =IFERROR(HistoricalFS!F30,0) -> 0.025186638 | G23: =IFERROR(HistoricalFS!G30,0) -> 0.022837459 | H23: =IFERROR(HistoricalFS!H30,0) -> 0.020802349 | I23: =IFERROR(HistoricalFS!I30,0) -> 0.01876857 | J23: =IFERROR(HistoricalFS!J30,0) -> 0.019645858 | ... L23: =IFERROR(HistoricalFS!L30,0) -> 0.020676925 | N23: =IFERROR(AVERAGE(C23:L23),0) -> 0.019037816 | O23: =IFERROR(MEDIAN(C23:L23),0) -> 0.020038491
B24: OperatingIncome%Sales | C24: =C18 -> 0.17779386 | D24: =D18 -> 0.19634266 | E24: =E18 -> 0.21152379 | F24: =F18 -> 0.22268306 | G24: =G18 -> 0.22437697 | H24: =H18 -> 0.22434504 | I24: =I18 -> 0.21475735 | J24: =J18 -> 0.21718689 | ... L24: =L18 -> 0.2126016 | N24: =IFERROR(AVERAGE(C24:L24),0) -> 0.21208422 | O24: =IFERROR(MEDIAN(C24:L24),0) -> 0.21597212
B26: Return on Capital Employed | C26: =IFERROR((HistoricalFS!C23-HistoricalFS!C29)/SUM(HistoricalFS!C54:C56),0) -> 0.83976642 | D26: =IFERROR((HistoricalFS!D23-HistoricalFS!D29)/SUM(HistoricalFS!D54:D56),0) -> 0.95852218 | E26: =IFERROR((HistoricalFS!E23-HistoricalFS!E29)/SUM(HistoricalFS!E54:E56),0) -> 1.0438112 | F26: =IFERROR((HistoricalFS!F23-HistoricalFS!F29)/SUM(HistoricalFS!F54:F56),0) -> 1.0765585 | G26: =IFERROR((HistoricalFS!G23-HistoricalFS!G29)/SUM(HistoricalFS!G54:G56),0) -> 0.22133658 | H26: =IFERROR((HistoricalFS!H23-HistoricalFS!H29)/SUM(HistoricalFS!H54:H56),0) -> 0.23483155 | I26: =IFERROR((HistoricalFS!I23-HistoricalFS!I29)/SUM(HistoricalFS!I54:I56),0) -> 0.25250859 | J26: =IFERROR((HistoricalFS!J23-HistoricalFS!J29)/SUM(HistoricalFS!J54:J56),0) -> 0.25507571 | ... L26: =IFERROR((HistoricalFS!L23-HistoricalFS!L29)/SUM(HistoricalFS!L54:L56),0) -> 0.27293546 | N26: =IFERROR(AVERAGE(C26:L26),0) -> 0.54187154 | O26: =IFERROR(MEDIAN(C26:L26),0) -> 0.26815235
B27: Retained Earnings % | C27: =IFERROR(HistoricalFS!C49,0) -> 0.054582904 | D27: =IFERROR(HistoricalFS!D49,0) -> 0.11366434 | E27: =IFERROR(HistoricalFS!E49,0) -> 0.17183688 | F27: =IFERROR(HistoricalFS!F49,0) -> 0.14718888 | G27: =IFERROR(HistoricalFS!G49,0) -> 0 | H27: =IFERROR(HistoricalFS!H49,0) -> 0.078750144 | I27: =IFERROR(HistoricalFS!I49,0) -> 0.054667354 | J27: =IFERROR(HistoricalFS!J49,0) -> 0 | ... L27: =IFERROR(HistoricalFS!L49,0) -> 0.049427782 | N27: =IFERROR(AVERAGE(C27:L27),0) -> 0.067011829 | O27: =IFERROR(MEDIAN(C27:L27),0) -> 0.054625129
B28: Return on Equity | C28: =IFERROR(HistoricalFS!C38/SUM(HistoricalFS!C54:C55),0) -> 0.57591934 | D28: =IFERROR(HistoricalFS!D38/SUM(HistoricalFS!D54:D55),0) -> 0.66941354 | E28: =IFERROR(HistoricalFS!E38/SUM(HistoricalFS!E54:E55),0) -> 0.72937587 | F28: =IFERROR(HistoricalFS!F38/SUM(HistoricalFS!F54:F55),0) -> 0.76947381 | G28: =IFERROR(HistoricalFS!G38/SUM(HistoricalFS!G54:G55),0) -> 0.16421949 | H28: =IFERROR(HistoricalFS!H38/SUM(HistoricalFS!H54:H55),0) -> 0.17677993 | I28: =IFERROR(HistoricalFS!I38/SUM(HistoricalFS!I54:I55),0) -> 0.19272821 | J28: =IFERROR(HistoricalFS!J38/SUM(HistoricalFS!J54:J55),0) -> 0.18479831 | ... L28: =IFERROR(HistoricalFS!L38/SUM(HistoricalFS!L54:L55),0) -> 0.20796487 | N28: =IFERROR(AVERAGE(C28:L28),0) -> 0.38592487 | O28: =IFERROR(MEDIAN(C28:L28),0) -> 0.20034654
B29: Self Sustained Growth Rate | C29: =IFERROR(C27*C28,0) -> 0.03143535 | D29: =IFERROR(D27*D28,0) -> 0.076088449 | E29: =IFERROR(E27*E28,0) -> 0.12533367 | F29: =IFERROR(F27*F28,0) -> 0.11325799 | G29: =IFERROR(G27*G28,0) -> 0 | H29: =IFERROR(H27*H28,0) -> 0.013921445 | I29: =IFERROR(I27*I28,0) -> 0.010535941 | J29: =IFERROR(J27*J28,0) -> 0 | ... L29: =IFERROR(L27*L28,0) -> 0.010279242 | N29: =IFERROR(AVERAGE(C29:L29),0) -> 0.038085209 | O29: =IFERROR(MEDIAN(C29:L29),0) -> 0.012228693
B30: Interest Coverage Ratio | C30: =IFERROR((HistoricalFS!C23-HistoricalFS!C29)/HistoricalFS!C26,0) -> 168.45714 | D30: =IFERROR((HistoricalFS!D23-HistoricalFS!D29)/HistoricalFS!D26,0) -> 268.42308 | E30: =IFERROR((HistoricalFS!E23-HistoricalFS!E29)/HistoricalFS!E26,0) -> 251.9697 | F30: =IFERROR((HistoricalFS!F23-HistoricalFS!F29)/HistoricalFS!F26,0) -> 75.076271 | G30: =IFERROR((HistoricalFS!G23-HistoricalFS!G29)/HistoricalFS!G26,0) -> 90.188034 | H30: =IFERROR((HistoricalFS!H23-HistoricalFS!H29)/HistoricalFS!H26,0) -> 111 | I30: =IFERROR((HistoricalFS!I23-HistoricalFS!I29)/HistoricalFS!I26,0) -> 114.12281 | J30: =IFERROR((HistoricalFS!J23-HistoricalFS!J29)/HistoricalFS!J26,0) -> 40.248503 | ... L30: =IFERROR((HistoricalFS!L23-HistoricalFS!L29)/HistoricalFS!L26,0) -> 33.429268 | N30: =IFERROR(AVERAGE(C30:L30),0) -> 118.82035 | O30: =IFERROR(MEDIAN(C30:L30),0) -> 100.59402
B32: Debtor Turnover Ratio | C32: =IFERROR(HistoricalFS!C11/HistoricalFS!C66,0) -> 30.564055 | D32: =IFERROR(HistoricalFS!D11/HistoricalFS!D66,0) -> 27.133588 | E32: =IFERROR(HistoricalFS!E11/HistoricalFS!E66,0) -> 21.646476 | F32: =IFERROR(HistoricalFS!F11/HistoricalFS!F66,0) -> 34.624021 | G32: =IFERROR(HistoricalFS!G11/HistoricalFS!G66,0) -> 26.750853 | H32: =IFERROR(HistoricalFS!H11/HistoricalFS!H66,0) -> 23.455277 | I32: =IFERROR(HistoricalFS!I11/HistoricalFS!I66,0) -> 19.675219 | J32: =IFERROR(HistoricalFS!J11/HistoricalFS!J66,0) -> 20.652653 | ... L32: =IFERROR(HistoricalFS!L11/HistoricalFS!L66,0) -> 19.079017 | N32: =IFERROR(AVERAGE(C32:L32),0) -> 23.963981 | O32: =IFERROR(MEDIAN(C32:L32),0) -> 22.550877
B33: Creditor Turnover Ratio | C33: =IFERROR(HistoricalFS!C11/HistoricalFS!C57,0) -> 3.8183074 | D33: =IFERROR(HistoricalFS!D11/HistoricalFS!D57,0) -> 3.3593233 | E33: =IFERROR(HistoricalFS!E11/HistoricalFS!E57,0) -> 3.6865798 | F33: =IFERROR(HistoricalFS!F11/HistoricalFS!F57,0) -> 3.3363804 | G33: =IFERROR(HistoricalFS!G11/HistoricalFS!G57,0) -> 2.2324124 | H33: =IFERROR(HistoricalFS!H11/HistoricalFS!H57,0) -> 2.5706303 | I33: =IFERROR(HistoricalFS!I11/HistoricalFS!I57,0) -> 2.8106152 | J33: =IFERROR(HistoricalFS!J11/HistoricalFS!J57,0) -> 2.4002792 | ... L33: =IFERROR(HistoricalFS!L11/HistoricalFS!L57,0) -> 2.1838014 | N33: =IFERROR(AVERAGE(C33:L33),0) -> 2.8526813 | O33: =IFERROR(MEDIAN(C33:L33),0) -> 2.6906228
B34: Inventory Turnover | C34: =IFERROR(HistoricalFS!C11/HistoricalFS!C67,0) -> 13.050767 | D34: =IFERROR(HistoricalFS!D11/HistoricalFS!D67,0) -> 14.144449 | E34: =IFERROR(HistoricalFS!E11/HistoricalFS!E67,0) -> 15.27195 | F34: =IFERROR(HistoricalFS!F11/HistoricalFS!F67,0) -> 14.377665 | G34: =IFERROR(HistoricalFS!G11/HistoricalFS!G67,0) -> 13.139983 | H34: =IFERROR(HistoricalFS!H11/HistoricalFS!H67,0) -> 12.804199 | I34: =IFERROR(HistoricalFS!I11/HistoricalFS!I67,0) -> 14.250765 | J34: =IFERROR(HistoricalFS!J11/HistoricalFS!J67,0) -> 15.389359 | ... L34: =IFERROR(HistoricalFS!L11/HistoricalFS!L67,0) -> 13.461683 | N34: =IFERROR(AVERAGE(C34:L34),0) -> 13.978165 | O34: =IFERROR(MEDIAN(C34:L34),0) -> 14.017638
B35: Fixed Asset Turnover | C35: =IFERROR(HistoricalFS!C11/HistoricalFS!C60,0) -> 7.5044128 | D35: =IFERROR(HistoricalFS!D11/HistoricalFS!D60,0) -> 7.8500442 | E35: =IFERROR(HistoricalFS!E11/HistoricalFS!E60,0) -> 8.3372216 | F35: =IFERROR(HistoricalFS!F11/HistoricalFS!F60,0) -> 7.2609965 | G35: =IFERROR(HistoricalFS!G11/HistoricalFS!G60,0) -> 0.91417686 | H35: =IFERROR(HistoricalFS!H11/HistoricalFS!H60,0) -> 1.0189031 | I35: =IFERROR(HistoricalFS!I11/HistoricalFS!I60,0) -> 1.1500057 | J35: =IFERROR(HistoricalFS!J11/HistoricalFS!J60,0) -> 1.151682 | ... L35: =IFERROR(HistoricalFS!L11/HistoricalFS!L60,0) -> 1.1225883 | N35: =IFERROR(AVERAGE(C35:L35),0) -> 3.7438733 | O35: =IFERROR(MEDIAN(C35:L35),0) -> 1.1508439
B36: Capital Turnover Ratio | C36: =IFERROR(HistoricalFS!C11/SUM(HistoricalFS!C54:C55),0) -> 4.9172598 | D36: =IFERROR(HistoricalFS!D11/SUM(HistoricalFS!D54:D55),0) -> 4.8818844 | E36: =IFERROR(HistoricalFS!E11/SUM(HistoricalFS!E54:E55),0) -> 4.9968222 | F36: =IFERROR(HistoricalFS!F11/SUM(HistoricalFS!F54:F55),0) -> 4.8344878 | G36: =IFERROR(HistoricalFS!G11/SUM(HistoricalFS!G54:G55),0) -> 0.98644964 | H36: =IFERROR(HistoricalFS!H11/SUM(HistoricalFS!H54:H55),0) -> 1.0689957 | I36: =IFERROR(HistoricalFS!I11/SUM(HistoricalFS!I54:I55),0) -> 1.204278 | J36: =IFERROR(HistoricalFS!J11/SUM(HistoricalFS!J54:J55),0) -> 1.2084814 | ... L36: =IFERROR(HistoricalFS!L11/SUM(HistoricalFS!L54:L55),0) -> 1.322719 | N36: =IFERROR(AVERAGE(C36:L36),0) -> 2.6662785 | O36: =IFERROR(MEDIAN(C36:L36),0) -> 1.2820631
B38: Debtor Days | C38: =IFERROR(365/C32,0) -> 11.942133 | D38: =IFERROR(365/D32,0) -> 13.451962 | E38: =IFERROR(365/E32,0) -> 16.861867 | F38: =IFERROR(365/F32,0) -> 10.541814 | G38: =IFERROR(365/G32,0) -> 13.644425 | H38: =IFERROR(365/H32,0) -> 15.56153 | I38: =IFERROR(365/I32,0) -> 18.551255 | J38: =IFERROR(365/J32,0) -> 17.673275 | ... L38: =IFERROR(365/L32,0) -> 19.130964 | N38: =IFERROR(AVERAGE(C38:L38),0) -> 16.00884 | O38: =IFERROR(MEDIAN(C38:L38),0) -> 16.211699
B39: Payable Days | C39: =IFERROR(365/C33,0) -> 95.592093 | D39: =IFERROR(365/D33,0) -> 108.65283 | E39: =IFERROR(365/E33,0) -> 99.007759 | F39: =IFERROR(365/F33,0) -> 109.39999 | G39: =IFERROR(365/G33,0) -> 163.50026 | H39: =IFERROR(365/H33,0) -> 141.98852 | I39: =IFERROR(365/I33,0) -> 129.86481 | J39: =IFERROR(365/J33,0) -> 152.06564 | ... L39: =IFERROR(365/L33,0) -> 167.13974 | N39: =IFERROR(AVERAGE(C39:L39),0) -> 133.86952 | O39: =IFERROR(MEDIAN(C39:L39),0) -> 135.92666
B40: Inventory Days | C40: =IFERROR(365/C34,0) -> 27.967704 | D40: =IFERROR(365/D34,0) -> 25.805177 | E40: =IFERROR(365/E34,0) -> 23.900025 | F40: =IFERROR(365/F34,0) -> 25.386597 | G40: =IFERROR(365/G34,0) -> 27.777813 | H40: =IFERROR(365/H34,0) -> 28.506273 | I40: =IFERROR(365/I34,0) -> 25.612661 | J40: =IFERROR(365/J34,0) -> 23.717688 | ... L40: =IFERROR(365/L34,0) -> 27.113995 | N40: =IFERROR(AVERAGE(C40:L40),0) -> 26.206427 | O40: =IFERROR(MEDIAN(C40:L40),0) -> 26.040755
B41: Cash Conversion Cycle (in days) | C41: =IFERROR(SUM(C38,C40)-C39,0) -> -55.682257 | D41: =IFERROR(SUM(D38,D40)-D39,0) -> -69.395696 | E41: =IFERROR(SUM(E38,E40)-E39,0) -> -58.245866 | F41: =IFERROR(SUM(F38,F40)-F39,0) -> -73.471583 | G41: =IFERROR(SUM(G38,G40)-G39,0) -> -122.07802 | H41: =IFERROR(SUM(H38,H40)-H39,0) -> -97.920718 | I41: =IFERROR(SUM(I38,I40)-I39,0) -> -85.700891 | J41: =IFERROR(SUM(J38,J40)-J39,0) -> -110.67468 | ... L41: =IFERROR(SUM(L38,L40)-L39,0) -> -120.89479 | N41: =IFERROR(AVERAGE(C41:L41),0) -> -91.654256 | O41: =IFERROR(MEDIAN(C41:L41),0) -> -91.810805
B43: CFO/Sales | C43: =IFERROR(HistoricalFS!C79/HistoricalFS!C11,0) -> 0.19636934 | D43: =IFERROR(HistoricalFS!D79/HistoricalFS!D11,0) -> 0.21057814 | E43: =IFERROR(HistoricalFS!E79/HistoricalFS!E11,0) -> 0.22663444 | F43: =IFERROR(HistoricalFS!F79/HistoricalFS!F11,0) -> 0.24440087 | G43: =IFERROR(HistoricalFS!G79/HistoricalFS!G11,0) -> 0.24819257 | H43: =IFERROR(HistoricalFS!H79/HistoricalFS!H11,0) -> 0.24461351 | I43: =IFERROR(HistoricalFS!I79/HistoricalFS!I11,0) -> 0.2325685 | J43: =IFERROR(HistoricalFS!J79/HistoricalFS!J11,0) -> 0.2348617 | ... L43: =IFERROR(HistoricalFS!L79/HistoricalFS!L11,0) -> 0.23504684 | N43: =IFERROR(AVERAGE(C43:L43),0) -> 0.23169067 | O43: =IFERROR(MEDIAN(C43:L43),0) -> 0.23495427
B44: CFO/Total Asset | C44: =IFERROR(HistoricalFS!C79/HistoricalFS!C71,0) -> 0.41461862 | D44: =IFERROR(HistoricalFS!D79/HistoricalFS!D71,0) -> 0.41904602 | E44: =IFERROR(HistoricalFS!E79/HistoricalFS!E71,0) -> 0.47823286 | F44: =IFERROR(HistoricalFS!F79/HistoricalFS!F71,0) -> 0.48245919 | G44: =IFERROR(HistoricalFS!G79/HistoricalFS!G71,0) -> 0.16979924 | H44: =IFERROR(HistoricalFS!H79/HistoricalFS!H71,0) -> 0.18195615 | I44: =IFERROR(HistoricalFS!I79/HistoricalFS!I71,0) -> 0.19279664 | J44: =IFERROR(HistoricalFS!J79/HistoricalFS!J71,0) -> 0.18521067 | ... L44: =IFERROR(HistoricalFS!L79/HistoricalFS!L71,0) -> 0.19003486 | N44: =IFERROR(AVERAGE(C44:L44),0) -> 0.29012496 | O44: =IFERROR(MEDIAN(C44:L44),0) -> 0.19141575
B45: CFO/Total Debt | C45: =IFERROR(HistoricalFS!C79/HistoricalFS!C56,0) -> 23.509025 | D45: =IFERROR(HistoricalFS!D79/HistoricalFS!D56,0) -> 0 | E45: =IFERROR(HistoricalFS!E79/HistoricalFS!E56,0) -> 89.989899 | F45: =IFERROR(HistoricalFS!F79/HistoricalFS!F56,0) -> 0 | G45: =IFERROR(HistoricalFS!G79/HistoricalFS!G56,0) -> 0 | H45: =IFERROR(HistoricalFS!H79/HistoricalFS!H56,0) -> 12.300096 | I45: =IFERROR(HistoricalFS!I79/HistoricalFS!I56,0) -> 11.557834 | J45: =IFERROR(HistoricalFS!J79/HistoricalFS!J56,0) -> 9.7958221 | ... L45: =IFERROR(HistoricalFS!L79/HistoricalFS!L56,0) -> 10.252368 | N45: =IFERROR(AVERAGE(C45:L45),0) -> 16.647179 | O45: =IFERROR(MEDIAN(C45:L45),0) -> 10.024095

Sheet Common Size Income Statement
B2: HINDUSTAN UNILEVER LTD
B3: (NSE: HINDUNILVR | BSE: 500696 )
B4: INR 1927.0
B5: 52 Week - (High- 2667.2 & Low- 1926.2)
B7: ="Common Size Income Statement"&" "&"-"&'Data Sheet'!$B$1 -> Common Size Income Statement -HINDUSTAN UNILEVER LTD
B9: Particilars | C9: ='Data Sheet'!B16 -> 42825 | D9: ='Data Sheet'!C16 -> 43190 | E9: ='Data Sheet'!D16 -> 43555 | F9: ='Data Sheet'!E16 -> 43921 | G9: ='Data Sheet'!F16 -> 44286 | H9: ='Data Sheet'!G16 -> 44651 | I9: ='Data Sheet'!H16 -> 45016 | J9: ='Data Sheet'!I16 -> 45382 | ... L9: ='Data Sheet'!K16 -> 46112
B11: ='Data Sheet'!A17 -> Sales | C11: ='Data Sheet'!B17/'Data Sheet'!B$17 -> 1 | D11: ='Data Sheet'!C17/'Data Sheet'!C$17 -> 1 | E11: ='Data Sheet'!D17/'Data Sheet'!D$17 -> 1 | F11: ='Data Sheet'!E17/'Data Sheet'!E$17 -> 1 | G11: ='Data Sheet'!F17/'Data Sheet'!F$17 -> 1 | H11: ='Data Sheet'!G17/'Data Sheet'!G$17 -> 1 | I11: ='Data Sheet'!H17/'Data Sheet'!H$17 -> 1 | J11: ='Data Sheet'!I17/'Data Sheet'!I$17 -> 1 | ... L11: ='Data Sheet'!K17/'Data Sheet'!K$17 -> 1
B12: ='Data Sheet'!A18 -> Raw Material Cost | C12: ='Data Sheet'!B18/'Data Sheet'!B$17 -> 0.41028888 | D12: ='Data Sheet'!C18/'Data Sheet'!C$17 -> 0.400422 | E12: ='Data Sheet'!D18/'Data Sheet'!D$17 -> 0.4030781 | F12: ='Data Sheet'!E18/'Data Sheet'!E$17 -> 0.39456552 | G12: ='Data Sheet'!F18/'Data Sheet'!F$17 -> 0.42827677 | H12: ='Data Sheet'!G18/'Data Sheet'!G$17 -> 0.43608664 | I12: ='Data Sheet'!H18/'Data Sheet'!H$17 -> 0.46924728 | J12: ='Data Sheet'!I18/'Data Sheet'!I$17 -> 0.4333398 | ... L12: ='Data Sheet'!K18/'Data Sheet'!K$17 -> 0.45228641
B13: ='Data Sheet'!A19 -> Change in Inventory | C13: ='Data Sheet'!B19/'Data Sheet'!B$17 -> -0.0043423195 | D13: ='Data Sheet'!C19/'Data Sheet'!C$17 -> 0.0020256014 | E13: ='Data Sheet'!D19/'Data Sheet'!D$17 -> -0.00030526584 | F13: ='Data Sheet'!E19/'Data Sheet'!E$17 -> 0.0027147274 | G13: ='Data Sheet'!F19/'Data Sheet'!F$17 -> 0.0086118908 | H13: ='Data Sheet'!G19/'Data Sheet'!G$17 -> 0.00041947908 | I13: ='Data Sheet'!H19/'Data Sheet'!H$17 -> 0.0012380324 | J13: ='Data Sheet'!I19/'Data Sheet'!I$17 -> 0.00017771746 | ... L13: ='Data Sheet'!K19/'Data Sheet'!K$17 -> 0.0066544642
B14: ='Data Sheet'!A20 -> Power and Fuel | C14: ='Data Sheet'!B20/'Data Sheet'!B$17 -> 0.008895724 | D14: ='Data Sheet'!C20/'Data Sheet'!C$17 -> 0.0082993389 | E14: ='Data Sheet'!D20/'Data Sheet'!D$17 -> 0.0078351564 | F14: ='Data Sheet'!E20/'Data Sheet'!E$17 -> 0.0075157731 | G14: ='Data Sheet'!F20/'Data Sheet'!F$17 -> 0.0072084715 | H14: ='Data Sheet'!G20/'Data Sheet'!G$17 -> 0.0060633795 | I14: ='Data Sheet'!H20/'Data Sheet'!H$17 -> 0.0063387257 | J14: ='Data Sheet'!I20/'Data Sheet'!I$17 -> 0.0072056353 | ... L14: ='Data Sheet'!K20/'Data Sheet'!K$17 -> 0.0066079295
B15: ='Data Sheet'!A21 -> Other Mfr. Exp | C15: ='Data Sheet'!B21/'Data Sheet'!B$17 -> 0.087057475 | D15: ='Data Sheet'!C21/'Data Sheet'!C$17 -> 0.08434379 | E15: ='Data Sheet'!D21/'Data Sheet'!D$17 -> 0.077359451 | F15: ='Data Sheet'!E21/'Data Sheet'!E$17 -> 0.073046276 | G15: ='Data Sheet'!F21/'Data Sheet'!F$17 -> 0.060984945 | H15: ='Data Sheet'!G21/'Data Sheet'!G$17 -> 0.063951493 | I15: ='Data Sheet'!H21/'Data Sheet'!H$17 -> 0.062578409 | J15: ='Data Sheet'!I21/'Data Sheet'!I$17 -> 0.05468851 | ... L15: ='Data Sheet'!K21/'Data Sheet'!K$17 -> 0.051250233
B16: ='Data Sheet'!A22 -> Employee Cost | C16: ='Data Sheet'!B22/'Data Sheet'!B$17 -> 0.052560159 | D16: ='Data Sheet'!C22/'Data Sheet'!C$17 -> 0.052328035 | E16: ='Data Sheet'!D22/'Data Sheet'!D$17 -> 0.047697787 | F16: ='Data Sheet'!E22/'Data Sheet'!E$17 -> 0.045748184 | G16: ='Data Sheet'!F22/'Data Sheet'!F$17 -> 0.050140342 | H16: ='Data Sheet'!G22/'Data Sheet'!G$17 -> 0.048526103 | I16: ='Data Sheet'!H22/'Data Sheet'!H$17 -> 0.047111258 | J16: ='Data Sheet'!I22/'Data Sheet'!I$17 -> 0.048613804 | ... L16: ='Data Sheet'!K22/'Data Sheet'!K$17 -> 0.04924924
B17: ='Data Sheet'!A23 -> Selling and admin | C17: ='Data Sheet'!B23/'Data Sheet'!B$17 -> 0.20170677 | D17: ='Data Sheet'!C23/'Data Sheet'!C$17 -> 0.20402307 | E17: ='Data Sheet'!D23/'Data Sheet'!D$17 -> 0.19832104 | F17: ='Data Sheet'!E23/'Data Sheet'!E$17 -> 0.1915391 | G17: ='Data Sheet'!F23/'Data Sheet'!F$17 -> 0.16811261 | H17: ='Data Sheet'!G23/'Data Sheet'!G$17 -> 0.15566487 | I17: ='Data Sheet'!H23/'Data Sheet'!H$17 -> 0.14501486 | J17: ='Data Sheet'!I23/'Data Sheet'!I$17 -> 0.17416311 | ... L17: ='Data Sheet'!K23/'Data Sheet'!K$17 -> 0.16665633
B18: ='Data Sheet'!A24 -> Other Expenses | C18: ='Data Sheet'!B24/'Data Sheet'!B$17 -> 0.044327845 | D18: ='Data Sheet'!C24/'Data Sheet'!C$17 -> 0.041637361 | E18: ='Data Sheet'!D24/'Data Sheet'!D$17 -> 0.039506487 | F18: ='Data Sheet'!E24/'Data Sheet'!E$17 -> 0.042430184 | G18: ='Data Sheet'!F24/'Data Sheet'!F$17 -> 0.046674322 | H18: ='Data Sheet'!G24/'Data Sheet'!G$17 -> 0.044979598 | I18: ='Data Sheet'!H24/'Data Sheet'!H$17 -> 0.037421591 | J18: ='Data Sheet'!I24/'Data Sheet'!I$17 -> 0.045334109 | ... L18: ='Data Sheet'!K24/'Data Sheet'!K$17 -> 0.047325805
B19: ='Data Sheet'!A25 -> Other Income | C19: ='Data Sheet'!B25/'Data Sheet'!B$17 -> 0.018273928 | D19: ='Data Sheet'!C25/'Data Sheet'!C$17 -> 0.0099310733 | E19: ='Data Sheet'!D25/'Data Sheet'!D$17 -> 0.0081912999 | F19: ='Data Sheet'!E25/'Data Sheet'!E$17 -> 0.010657819 | G19: ='Data Sheet'!F25/'Data Sheet'!F$17 -> 0.0036148677 | H19: ='Data Sheet'!G25/'Data Sheet'!G$17 -> 0.0041757236 | I19: ='Data Sheet'!H25/'Data Sheet'!H$17 -> 0.0073951799 | J19: ='Data Sheet'!I25/'Data Sheet'!I$17 -> 0.013199561 | ... L19: ='Data Sheet'!K25/'Data Sheet'!K$17 -> 0.076363467
B20: ='Data Sheet'!A26 -> Depreciation | C20: ='Data Sheet'!B26/'Data Sheet'!B$17 -> 0.013026959 | D20: ='Data Sheet'!C26/'Data Sheet'!C$17 -> 0.014629343 | E20: ='Data Sheet'!D26/'Data Sheet'!D$17 -> 0.014372933 | F20: ='Data Sheet'!E26/'Data Sheet'!E$17 -> 0.025186638 | G20: ='Data Sheet'!F26/'Data Sheet'!F$17 -> 0.022837459 | H20: ='Data Sheet'!G26/'Data Sheet'!G$17 -> 0.020802349 | I20: ='Data Sheet'!H26/'Data Sheet'!H$17 -> 0.01876857 | J20: ='Data Sheet'!I26/'Data Sheet'!I$17 -> 0.019645858 | ... L20: ='Data Sheet'!K26/'Data Sheet'!K$17 -> 0.020676925
B21: ='Data Sheet'!A27 -> Interest | C21: ='Data Sheet'!B27/'Data Sheet'!B$17 -> 0.0010554249 | D21: ='Data Sheet'!C27/'Data Sheet'!C$17 -> 0.00073146715 | E21: ='Data Sheet'!D27/'Data Sheet'!D$17 -> 0.00083948105 | F21: ='Data Sheet'!E27/'Data Sheet'!E$17 -> 0.002966091 | G21: ='Data Sheet'!F27/'Data Sheet'!F$17 -> 0.0024878796 | H21: ='Data Sheet'!G27/'Data Sheet'!G$17 -> 0.0020211265 | I21: ='Data Sheet'!H27/'Data Sheet'!H$17 -> 0.0018818092 | J21: ='Data Sheet'!I27/'Data Sheet'!I$17 -> 0.0053961484 | ... L21: ='Data Sheet'!K27/'Data Sheet'!K$17 -> 0.0063597444
B22: ='Data Sheet'!A28 -> Profit before tax | C22: ='Data Sheet'!B28/'Data Sheet'!B$17 -> 0.19501236 | D22: ='Data Sheet'!C28/'Data Sheet'!C$17 -> 0.20554227 | E22: ='Data Sheet'!D28/'Data Sheet'!D$17 -> 0.2188756 | F22: ='Data Sheet'!E28/'Data Sheet'!E$17 -> 0.23037478 | G22: ='Data Sheet'!F28/'Data Sheet'!F$17 -> 0.22550396 | H22: ='Data Sheet'!G28/'Data Sheet'!G$17 -> 0.22649964 | I22: ='Data Sheet'!H28/'Data Sheet'!H$17 -> 0.22027072 | J22: ='Data Sheet'!I28/'Data Sheet'!I$17 -> 0.22499031 | ... L22: ='Data Sheet'!K28/'Data Sheet'!K$17 -> 0.28260532
... B25: ='Data Sheet'!A31 -> Dividend Amount | C25: ='Data Sheet'!B31/'Data Sheet'!B$17 -> 0.11072915 | D25: ='Data Sheet'!C31/'Data Sheet'!C$17 -> 0.12153608 | E25: ='Data Sheet'!D31/'Data Sheet'!D$17 -> 0.12088527 | F25: ='Data Sheet'!E31/'Data Sheet'!E$17 -> 0.13573637 | G25: ='Data Sheet'!F31/'Data Sheet'!F$17 -> 0.20237943 | H25: ='Data Sheet'!G31/'Data Sheet'!G$17 -> 0.15234718 | I25: ='Data Sheet'!H31/'Data Sheet'!H$17 -> 0.15128755 | J25: ='Data Sheet'!I31/'Data Sheet'!I$17 -> 0.15946103 | ... L25: ='Data Sheet'!K31/'Data Sheet'!K$17 -> 0.14945399
B26: ='Data Sheet'!A34 -> EBITDA | C26: ='Data Sheet'!B34/'Data Sheet'!B$17 -> 0.20867258 | D26: ='Data Sheet'!C34/'Data Sheet'!C$17 -> 0.22053735 | E26: ='Data Sheet'!D34/'Data Sheet'!D$17 -> 0.23393539 | F26: ='Data Sheet'!E34/'Data Sheet'!E$17 -> 0.25832642 | G26: ='Data Sheet'!F34/'Data Sheet'!F$17 -> 0.25074424 | H26: ='Data Sheet'!G34/'Data Sheet'!G$17 -> 0.24907524 | I26: ='Data Sheet'!H34/'Data Sheet'!H$17 -> 0.24054143 | J26: ='Data Sheet'!I34/'Data Sheet'!I$17 -> 0.24995153 | ... L26: ='Data Sheet'!K34/'Data Sheet'!K$17 -> 0.30934727
B29: ="Common Size Balance Sheet"&" "&"-"&'Data Sheet'!$B$1 -> Common Size Balance Sheet -HINDUSTAN UNILEVER LTD
B31: Particilars | C31: ='Data Sheet'!B56 -> 42825 | D31: ='Data Sheet'!C56 -> 43190 | E31: ='Data Sheet'!D56 -> 43555 | F31: ='Data Sheet'!E56 -> 43921 | G31: ='Data Sheet'!F56 -> 44286 | H31: ='Data Sheet'!G56 -> 44651 | I31: ='Data Sheet'!H56 -> 45016 | J31: ='Data Sheet'!I56 -> 45382 | ... L31: ='Data Sheet'!K56 -> 46112
B33: Total Liabilities | C33: ='Data Sheet'!B61/'Data Sheet'!B$61 -> 1 | D33: ='Data Sheet'!C61/'Data Sheet'!C$61 -> 1 | E33: ='Data Sheet'!D61/'Data Sheet'!D$61 -> 1 | F33: ='Data Sheet'!E61/'Data Sheet'!E$61 -> 1 | G33: ='Data Sheet'!F61/'Data Sheet'!F$61 -> 1 | H33: ='Data Sheet'!G61/'Data Sheet'!G$61 -> 1 | I33: ='Data Sheet'!H61/'Data Sheet'!H$61 -> 1 | J33: ='Data Sheet'!I61/'Data Sheet'!I$61 -> 1 | ... L33: ='Data Sheet'!K61/'Data Sheet'!K$61 -> 1
B34: ='Data Sheet'!A57 -> Equity Share Capital | C34: ='Data Sheet'!B57/'Data Sheet'!B$61 -> 0.013752706 | D34: ='Data Sheet'!C57/'Data Sheet'!C$61 -> 0.012092711 | E34: ='Data Sheet'!D57/'Data Sheet'!D$61 -> 0.011594825 | F34: ='Data Sheet'!E57/'Data Sheet'!E$61 -> 0.010718007 | G34: ='Data Sheet'!F57/'Data Sheet'!F$61 -> 0.0034186791 | H34: ='Data Sheet'!G57/'Data Sheet'!G$61 -> 0.0033330497 | I34: ='Data Sheet'!H57/'Data Sheet'!H$61 -> 0.0032157861 | J34: ='Data Sheet'!I57/'Data Sheet'!I$61 -> 0.0029940501 | ... L34: ='Data Sheet'!K57/'Data Sheet'!K$61 -> 0.0029471519
B35: ='Data Sheet'!A58 -> Reserves | C35: ='Data Sheet'!B58/'Data Sheet'!B$61 -> 0.41563734 | D35: ='Data Sheet'!C58/'Data Sheet'!C$61 -> 0.39553242 | E35: ='Data Sheet'!D58/'Data Sheet'!D$61 -> 0.41070374 | F35: ='Data Sheet'!E58/'Data Sheet'!E$61 -> 0.3976083 | G35: ='Data Sheet'!F58/'Data Sheet'!F$61 -> 0.6901222 | H35: ='Data Sheet'!G58/'Data Sheet'!G$61 -> 0.69250844 | I35: ='Data Sheet'!H58/'Data Sheet'!H$61 -> 0.68515402 | J35: ='Data Sheet'!I58/'Data Sheet'!I$61 -> 0.64955599 | ... L35: ='Data Sheet'!K58/'Data Sheet'!K$61 -> 0.60829216
B36: ='Data Sheet'!A59 -> Borrowings | C36: ='Data Sheet'!B59/'Data Sheet'!B$61 -> 0.017636572 | D36: ='Data Sheet'!C59/'Data Sheet'!C$61 -> 0 | E36: ='Data Sheet'!D59/'Data Sheet'!D$61 -> 0.0053142949 | F36: ='Data Sheet'!E59/'Data Sheet'!E$61 -> 0 | G36: ='Data Sheet'!F59/'Data Sheet'!F$61 -> 0 | H36: ='Data Sheet'!G59/'Data Sheet'!G$61 -> 0.014793067 | I36: ='Data Sheet'!H59/'Data Sheet'!H$61 -> 0.016681035 | J36: ='Data Sheet'!I59/'Data Sheet'!I$61 -> 0.018907108 | ... L36: ='Data Sheet'!K59/'Data Sheet'!K$61 -> 0.018535704
B37: ='Data Sheet'!A60 -> Other Liabilities | C37: ='Data Sheet'!B60/'Data Sheet'!B$61 -> 0.55297339 | D37: ='Data Sheet'!C60/'Data Sheet'!C$61 -> 0.59237487 | E37: ='Data Sheet'!D60/'Data Sheet'!D$61 -> 0.57238714 | F37: ='Data Sheet'!E60/'Data Sheet'!E$61 -> 0.5916737 | G37: ='Data Sheet'!F60/'Data Sheet'!F$61 -> 0.30645912 | H37: ='Data Sheet'!G60/'Data Sheet'!G$61 -> 0.28936544 | I37: ='Data Sheet'!H60/'Data Sheet'!H$61 -> 0.29494916 | J37: ='Data Sheet'!I60/'Data Sheet'!I$61 -> 0.32854285 | ... L37: ='Data Sheet'!K60/'Data Sheet'!K$61 -> 0.37022499
B39: Total Assset | C39: ='Data Sheet'!B75/'Data Sheet'!B$75 -> 1 | D39: ='Data Sheet'!C75/'Data Sheet'!C$75 -> 1 | E39: ='Data Sheet'!D75/'Data Sheet'!D$75 -> 1 | F39: ='Data Sheet'!E75/'Data Sheet'!E$75 -> 1 | G39: ='Data Sheet'!F75/'Data Sheet'!F$75 -> 1 | H39: ='Data Sheet'!G75/'Data Sheet'!G$75 -> 1 | I39: ='Data Sheet'!H75/'Data Sheet'!H$75 -> 1 | J39: ='Data Sheet'!I75/'Data Sheet'!I$75 -> 1 | ... L39: ='Data Sheet'!K75/'Data Sheet'!K$75 -> 1
B40: ='Data Sheet'!A62 -> Net Block | C40: ='Data Sheet'!B62/'Data Sheet'!B$75 -> 0.28135744 | D40: ='Data Sheet'!C62/'Data Sheet'!C$75 -> 0.25349905 | E40: ='Data Sheet'!D62/'Data Sheet'!D$75 -> 0.25310001 | F40: ='Data Sheet'!E62/'Data Sheet'!E$75 -> 0.27187019 | G40: ='Data Sheet'!F62/'Data Sheet'!F$75 -> 0.74837067 | H40: ='Data Sheet'!G62/'Data Sheet'!G$75 -> 0.73005134 | I40: ='Data Sheet'!H62/'Data Sheet'!H$75 -> 0.72085608 | J40: ='Data Sheet'!I62/'Data Sheet'!I$75 -> 0.68473289 | ... L40: ='Data Sheet'!K62/'Data Sheet'!K$75 -> 0.72020868
B41: ='Data Sheet'!A63 -> Capital Work in Progress | C41: ='Data Sheet'!B63/'Data Sheet'!B$75 -> 0.014580415 | D41: ='Data Sheet'!C63/'Data Sheet'!C$75 -> 0.02580898 | E41: ='Data Sheet'!D63/'Data Sheet'!D$75 -> 0.021793977 | F41: ='Data Sheet'!E63/'Data Sheet'!E$75 -> 0.029623381 | G41: ='Data Sheet'!F63/'Data Sheet'!F$75 -> 0.01083794 | H41: ='Data Sheet'!G63/'Data Sheet'!G$75 -> 0.018622529 | I41: ='Data Sheet'!H63/'Data Sheet'!H$75 -> 0.01549051 | J41: ='Data Sheet'!I63/'Data Sheet'!I$75 -> 0.013059155 | ... L41: ='Data Sheet'!K63/'Data Sheet'!K$75 -> 0.011036143
B42: ='Data Sheet'!A64 -> Investments | C42: ='Data Sheet'!B64/'Data Sheet'!B$75 -> 0.24156373 | D42: ='Data Sheet'!C64/'Data Sheet'!C$75 -> 0.16084425 | E42: ='Data Sheet'!D64/'Data Sheet'!D$75 -> 0.14579419 | F42: ='Data Sheet'!E64/'Data Sheet'!E$75 -> 0.062273607 | G42: ='Data Sheet'!F64/'Data Sheet'!F$75 -> 0.039409369 | H42: ='Data Sheet'!G64/'Data Sheet'!G$75 -> 0.049939012 | I42: ='Data Sheet'!H64/'Data Sheet'!H$75 -> 0.039437853 | J42: ='Data Sheet'!I64/'Data Sheet'!I$75 -> 0.058925455 | ... L42: ='Data Sheet'!K64/'Data Sheet'!K$75 -> 0.054666533
B43: ='Data Sheet'!A65 -> Other Assets | C43: ='Data Sheet'!B74/'Data Sheet'!B$75 -> 0.11524258 | D43: ='Data Sheet'!C74/'Data Sheet'!C$75 -> 0.15071101 | E43: ='Data Sheet'!D74/'Data Sheet'!D$75 -> 0.14198293 | F43: ='Data Sheet'!E74/'Data Sheet'!E$75 -> 0.18821019 | G43: ='Data Sheet'!F74/'Data Sheet'!F$75 -> 0.058699447 | H43: ='Data Sheet'!G74/'Data Sheet'!G$75 -> 0.057030607 | I43: ='Data Sheet'!H74/'Data Sheet'!H$75 -> 0.059895726 | J43: ='Data Sheet'!I74/'Data Sheet'!I$75 -> 0.057549466 | ... L43: ='Data Sheet'!K74/'Data Sheet'!K$75 -> 0.070919762
B44: ='Data Sheet'!A67 -> Receivables | C44: ='Data Sheet'!B67/'Data Sheet'!B$75 -> 0.06908188 | D44: ='Data Sheet'!C67/'Data Sheet'!C$75 -> 0.073340052 | E44: ='Data Sheet'!D67/'Data Sheet'!D$75 -> 0.09748242 | F44: ='Data Sheet'!E67/'Data Sheet'!E$75 -> 0.057013844 | G44: ='Data Sheet'!F67/'Data Sheet'!F$75 -> 0.025574629 | H44: ='Data Sheet'!G67/'Data Sheet'!G$75 -> 0.031713613 | I44: ='Data Sheet'!H67/'Data Sheet'!H$75 -> 0.04213364 | J44: ='Data Sheet'!I67/'Data Sheet'!I$75 -> 0.038183695 | ... L44: ='Data Sheet'!K67/'Data Sheet'!K$75 -> 0.042376282
B45: ='Data Sheet'!A68 -> Inventory | C45: ='Data Sheet'!B68/'Data Sheet'!B$75 -> 0.1617853 | D45: ='Data Sheet'!C68/'Data Sheet'!C$75 -> 0.14068973 | E45: ='Data Sheet'!D68/'Data Sheet'!D$75 -> 0.13817167 | F45: ='Data Sheet'!E68/'Data Sheet'!E$75 -> 0.13729966 | G45: ='Data Sheet'!F68/'Data Sheet'!F$75 -> 0.052065755 | H45: ='Data Sheet'!G68/'Data Sheet'!G$75 -> 0.058094347 | I45: ='Data Sheet'!H68/'Data Sheet'!H$75 -> 0.058171518 | J45: ='Data Sheet'!I68/'Data Sheet'!I$75 -> 0.051242849 | ... L45: ='Data Sheet'!K68/'Data Sheet'!K$75 -> 0.060059194
B46: ='Data Sheet'!A69 -> Cash & Bank | C46: ='Data Sheet'!B69/'Data Sheet'!B$75 -> 0.11638864 | D46: ='Data Sheet'!C69/'Data Sheet'!C$75 -> 0.19510693 | E46: ='Data Sheet'!D69/'Data Sheet'!D$75 -> 0.20167481 | F46: ='Data Sheet'!E69/'Data Sheet'!E$75 -> 0.25370913 | G46: ='Data Sheet'!F69/'Data Sheet'!F$75 -> 0.065042188 | H46: ='Data Sheet'!G69/'Data Sheet'!G$75 -> 0.054548549 | I46: ='Data Sheet'!H69/'Data Sheet'!H$75 -> 0.064014669 | J46: ='Data Sheet'!I69/'Data Sheet'!I$75 -> 0.096306489 | ... L46: ='Data Sheet'!K69/'Data Sheet'!K$75 -> 0.040733402

Sheet DCF>

Sheet WACC
B2: HINDUSTAN UNILEVER LTD
B3: (NSE: HINDUNILVR | BSE: 500696 )
B4: INR 1927.0
B5: 52 Week - (High- 2667.2 & Low- 1926.2)
B7: Weighted Average Cost of Capital
B9: All figures are in INR unless stated .
B11: Peer Comps
I12: Debt/ | J12: Debt/ | K12: Levered | L12: Unlevered
B13: Name of the company | E13: Country | F13: Total Debt | G13: Total Equity | H13: Tax Rate 1 | I13: Equity | J13: Capital | K13: Beta 2 | L13: Beta 3
B15: Hind. Unilever | E15: India | F15: ='Beta Comps'!F11 -> 1478 | G15: ='Beta Comps'!E11 -> 452766.24 | H15: 0.3 | I15: =F15/G15 -> 0.0032643777 | J15: =F15/(F15+G15) -> 0.0032537562 | K15: =Levered_Raw_Beta -> 0.55799676 | L15: =K15/(1+(1-H15)*I15) -> 0.55672461
B16: ITC | E16: India | F16: ='Beta Comps'!F12 -> 2399.06 | G16: ='Beta Comps'!E12 -> 325586.39 | H16: 0.3 | I16: =F16/G16 -> 0.0073684284 | J16: =F16/(F16+G16) -> 0.0073145318 | K16: 0.55 | L16: =K16/(1+(1-H16)*I16) -> 0.54717771
B17: Nestle India | E17: India | F17: ='Beta Comps'!F13 -> 444.16 | G17: ='Beta Comps'!E13 -> 266743.72 | H17: 0.3 | I17: =F17/G17 -> 0.0016651189 | J17: =F17/(F17+G17) -> 0.0016623509 | K17: 0.82 | L17: =K17/(1+(1-H17)*I17) -> 0.81904533
B18: Varun Beverages | E18: India | F18: ='Beta Comps'!F14 -> 2508.18 | G18: ='Beta Comps'!E14 -> 140879.66 | H18: 0.3 | I18: =F18/G18 -> 0.017803706 | J18: =F18/(F18+G18) -> 0.017492278 | K18: 1.06 | L18: =K18/(1+(1-H18)*I18) -> 1.0469523
B19: Britannia Inds. | E19: India | F19: ='Beta Comps'!F15 -> 1380.28 | G19: ='Beta Comps'!E15 -> 119518.85 | H19: 0.3 | I19: =F19/G19 -> 0.011548639 | J19: =F19/(F19+G19) -> 0.01141679 | K19: 0.52 | L19: =K19/(1+(1-H19)*I19) -> 0.51583001
G21: Average | H21: =AVERAGE(H15:H19) -> 0.3 | I21: =AVERAGE(I15:I19) -> 0.0083300538 | J21: =AVERAGE(J15:J19) -> 0.0082279415 | K21: =AVERAGE(K15:K19) -> 0.70159935 | L21: =AVERAGE(L15:L19) -> 0.69714598
G22: Median | H22: =MEDIAN(H15:H19) -> 0.3 | I22: =MEDIAN(I15:I19) -> 0.0073684284 | J22: =MEDIAN(J15:J19) -> 0.0073145318 | K22: =MEDIAN(K15:K19) -> 0.55799676 | L22: =MEDIAN(L15:L19) -> 0.55672461
B25: Cost of Debt | G25: Cost of Equity
B27: Pre-Tax Cost of Debt | E27: =HistoricalFS!M26/WACC!F15 -> 0.24560217 | G27: Risk Free Rate | H27: 0.07021
B28: Tax Rate | E28: =H22 -> 0.3 | G28: Equity Risk Premium | H28: =Rm!F16-WACC!H27 -> 0.081282308
B29: Post Tax Cost Of Debt | E29: =E27*(1-E28) -> 0.17192152 | G29: Levered Beta 4 | H29: =H38 -> 0.55959614
G30: Cost of Equity | H30: =H27+(H28*H29) -> 0.11569527
B33: Capital Structure | G33: Levered Beta
D35: Current | E35: Target | G35: Comps Median Unlevered Beta | H35: =L22 -> 0.55672461
B36: Total Debt | C36: =F15 -> 1478 | D36: =C36/$C$38 -> 0.0032537562 | E36: =J22 -> 0.0073145318 | G36: Target Debt/ Equity | H36: =E40 -> 0.0073684284
B37: Market Capilitalization | C37: =G15 -> 452766.24 | D37: =C37/$C$38 -> 0.99674624 | E37: =E38-E36 -> 0.99268547 | G37: Tax Rate | H37: =E28 -> 0.3
B38: Total Capital | C38: =SUM(C36:C37) -> 454244.24 | D38: =SUM(D36:D37) -> 1 | E38: =D38 -> 1 | G38: Levered Beta | H38: =H35*(1+(1-H37)*H36) -> 0.55959614
B40: Debt/ Equity | D40: =D36/D37 -> 0.0032643777 | E40: =E36/E37 -> 0.0073684284 | G40: Weighted Average Cost Of Capital
B42: Notes | G42: Cost of Equity | H42: =H30 -> 0.11569527
B43: 1. Tax Rate are considered as Marginal Tax Rate for the country | G43: Equity Weight | H43: =E37 -> 0.99268547
B44: 2. Levered Beta is based on 5 year monthly data
B45: 3. Unlevered Beta = Levered Beta /(1+(1- Tax Rate )* Debt / Equity) | G45: Cost of Debt | H45: =E29 -> 0.17192152
B46: 4. Levered Beta = Unlevered Beta * (1+(1- Tax Rate )* Debt / Equity) | G46: Debt Weight | H46: =E36 -> 0.0073145318
G48: WACC | H48: =(H42*H43)+(H45*H46) -> 0.11610653

Sheet Beta Regression
B2: HINDUSTAN UNILEVER LTD
B3: (NSE: HINDUNILVR | BSE: 500696 )
B4: INR 1927.0
B5: 52 Week - (High- 2667.2 & Low- 1926.2)
B7: Regression Beta Calculation - 2 years weekly
B9: Hindustan Unilever Limited Weekly Returns | F9: Nifty Weekly Returns | I9: Beta Drifting
B11: Date | C11: Closing Price | D11: Weekly Return | F11: Closing Price | G11: Weekly Return | I11: Levered Raw Beta | J11: =M14 -> 0.55799676 | L11: Beta 1 | M11: =SLOPE(D13:D117,G13:G117) -> 0.55799676
B12: 45544 | C12: 2818 | F12: 25356.5 | I12: Raw Beta Weight | J12: 0.75 | L12: Beta 2 | M12: =_xlfn.COVARIANCE.S(D12:D117,G12:G117)/_xlfn.VAR.S(G12:G117) -> 0.55799676
B13: 45551 | C13: 2860.9 | D13: =C13/C12-1 -> 0.015223563 | F13: 25790.95 | G13: =F13/F12-1 -> 0.017133674
